Workbook
Name Annual_Rtns: INDIRECT([1]Analytics!$G$1)
Name Holidays: [2]Holidays!$A$3:$A$2001
Name IQ_CH: 110000
Name IQ_CQ: 5000
Name IQ_CY: 10000
Name IQ_DAILY: 500000
Name IQ_FH: 100000
Name IQ_FQ: 500
Name IQ_FY: 1000
Name IQ_LTM: 2000
Name IQ_MONTH: 15000
Name IQ_NTM: 6000
Name IQ_WEEK: 50000
Name IQ_YTD: 3000
Name max_alloc: [3]Parameters!$O$2
Name MaxLeverage: #REF!
Name OLE_LINK1: 'Daily Returns'!#REF!
Name OLE_LINK1: Dashboard!#REF!
Name OLE_LINK1: 'Index Levels'!#REF!
Name OLE_LINK1: 'Index Levels - Full'!#REF!
Name OLE_LINK2: Dashboard!#REF!
Name OLE_LINK3: Dashboard!#REF!
Name TargetVol: #REF!
Name USAHolidays: [4]Holidays!$A:$A
Name vol_budget: [3]Parameters!$O$3

Sheet __FDSCACHE__
B1: This sheet contains FactSet XML data for use with this workbook's =FDS codes. Modifying the worksheet's contents may damage the workbook's =FDS functionality.

Sheet Dashboard
F2: S&P DJI Multi-Asset Indices
F3: spdji-multiasset@spglobal.com
B4: Dashboard: S&P 500® FC TCA 0.50% Decrement Index (USD) ER
F5: =MAX('Index Levels'!A:A) -> 46234
A8: Performance Summary
C17: Return
A18: Index | C18: 1-Month | D18: QTD | E18: YTD | F18: 12-Month
A19: Index
A20: =Performance!B6 -> S&P 500 FC TCA 0.50% Decrement Index (USD) ER | C20: =Performance!C6 -> -0.018640114 | D20: =Performance!D6 -> -0.018640114 | E20: =Performance!E6 -> 0.0096897624 | F20: =Performance!F6 -> -0.0099443632
A21: =Performance!B7 -> S&P 500 | C21: =Performance!C7 -> -0.0012846572 | D21: =Performance!D7 -> -0.0012846572 | E21: =Performance!E7 -> 0.09410849 | F21: =Performance!F7 -> 0.18145743
A38: Asset Class Exposures
D39: =F5 -> 46234 | F39: (End of Month)
D40: Equities | F40: Total
A41: S&P 500 FC TCA 0.50% Decrement Index (USD) ER | D41: ='Asset Class Exposures'!K19 -> 0.61270038 | F41: =D41 -> 0.61270038
D42: 12-Month Average
D43: Equities | F43: Total
A44: S&P 500 FC TCA 0.50% Decrement Index (USD) ER | D44: ='Asset Class Exposures'!F23 -> 0.9339335 | F44: =D44 -> 0.9339335
A61: The S&P 500 FC TCA Indices are based in part on “Fast Convergence” methodology developed and licensed by Bank of America Corporation and BofA Securities, Inc. (“BofA”). The index was developed in collaboration with BofA
A62: For Institutional Use Only; Not for use with Retail Investors
A63: Source: S&P Dow Jones Indices LLC. Data as of Jul. 31, 2026. Index performance based on returns in USD. Charts and tables are provided for illustrative purposes. Past performance is no guarantee of future results. All data prior to index launch date is back-tested hypothetical data. Chart is provided for illustrative purposes and reflects hypothetical historical performance. Please see the Performance Disclosure for more information regarding the inherent limitations associated with back-tested performance. https://legal.spindices.com/legal/trademarknotices-and-disclaimers/general-disclaimer-and-performance-disclosures

Sheet Disclaimer
A1: Dashboard: S&P 500 FC TCA 0.50% Decrement Index (USD) ER | E1: =Dashboard!F5 -> 46234
A5: GENERAL DISCLAIMER
A47: CONTACT US: | C47: New York | D47: +1.212.438.7354
B48: index_services@spglobal.com | C48: Toronto | D48: +1.212.438.7354
C49: London | D49: +44.20.7176.8888
C50: Tokyo | D50: +813.4550.8564
C51: Beijing | D51: +86.10.6569.2770
C52: Sydney | D52: +61.2.9255.9802
C53: Mumbai | D53: +91.22.272.5312
C54: Dubai | D54: +971.(0)4.371.7131
B56: www.spglobal.com/spdji

Sheet Performance
B2: Start Date | C2: =EOMONTH(C3,-1) -> 46203 | D2: {=_xlfn.IFS(MONTH(D3)=1,EOMONTH(D3,-1),MONTH(D3)=2,EOMONTH(D3,-2),MONTH(D3)=3,EOMONTH(D3,-3),MONTH(D3)=4,EOMONTH(D3,-1),MONTH(D3)=5,EOMONTH(D3,-2),MONTH(D3)=6,EOMONTH(D3,-3),MONTH(D3)=7,EOMONTH(D3,-1),MONTH(D3)=8,EOMONTH(D3,-2),MONTH(D3)=9,EOMONTH(D3,-3),MONTH(D3)=10,EOMONTH(D3,-1),MONTH(D3)=11,EOMONTH(D3,-2),MONTH(D3)=12,EOMONTH(D3,-3))} -> 46203 | E2: =DATE(YEAR(E3)-1,12,31) -> 46022 | F2: =EOMONTH(F3,-12) -> 45869
B3: End Date | C3: {=INDEX('Index Levels'!A3:A1048576,COUNT('Index Levels'!A3:A1048576),0)} -> 46234 | D3: =$C$3 -> 46234 | E3: =$C$3 -> 46234 | F3: =$C$3 -> 46234
C5: 1 Month | D5: QTD | E5: YTD | F5: 12 Month
B6: ='Index Levels - Full'!B1 -> S&P 500 FC TCA 0.50% Decrement Index (USD) ER | C6: =INDEX('Index Levels - Full'!$B:$B,MATCH(Performance!C$3,'Index Levels - Full'!$A:$A,0))/INDEX('Index Levels - Full'!$B:$B,MATCH(Performance!C$2,'Index Levels - Full'!$A:$A,0))-1 -> -0.018640114 | D6: =INDEX('Index Levels - Full'!$B:$B,MATCH(Performance!D$3,'Index Levels - Full'!$A:$A,0))/INDEX('Index Levels - Full'!$B:$B,MATCH(Performance!D$2,'Index Levels - Full'!$A:$A,0))-1 -> -0.018640114 | E6: =INDEX('Index Levels - Full'!$B:$B,MATCH(Performance!E$3,'Index Levels - Full'!$A:$A,0))/INDEX('Index Levels - Full'!$B:$B,MATCH(Performance!E$2,'Index Levels - Full'!$A:$A,0))-1 -> 0.0096897624 | F6: =INDEX('Index Levels - Full'!$B:$B,MATCH(Performance!F$3,'Index Levels - Full'!$A:$A,0))/INDEX('Index Levels - Full'!$B:$B,MATCH(Performance!F$2,'Index Levels - Full'!$A:$A,0))-1 -> -0.0099443632
B7: ='Index Levels - Full'!C1 -> S&P 500 | C7: =INDEX('Index Levels - Full'!$C:$C,MATCH(Performance!C$3,'Index Levels - Full'!$A:$A,0))/INDEX('Index Levels - Full'!$C:$C,MATCH(Performance!C$2,'Index Levels - Full'!$A:$A,0))-1 -> -0.0012846572 | D7: =INDEX('Index Levels - Full'!$C:$C,MATCH(Performance!D$3,'Index Levels - Full'!$A:$A,0))/INDEX('Index Levels - Full'!$C:$C,MATCH(Performance!D$2,'Index Levels - Full'!$A:$A,0))-1 -> -0.0012846572 | E7: =INDEX('Index Levels - Full'!$C:$C,MATCH(Performance!E$3,'Index Levels - Full'!$A:$A,0))/INDEX('Index Levels - Full'!$C:$C,MATCH(Performance!E$2,'Index Levels - Full'!$A:$A,0))-1 -> 0.09410849 | F7: =INDEX('Index Levels - Full'!$C:$C,MATCH(Performance!F$3,'Index Levels - Full'!$A:$A,0))/INDEX('Index Levels - Full'!$C:$C,MATCH(Performance!F$2,'Index Levels - Full'!$A:$A,0))-1 -> 0.18145743

Sheet 12 Month Rolling Return
B2: Start Date | C2: =EOMONTH(C3,-12) -> 45535 | D2: =EOMONTH(D3,-12) -> 45565 | E2: =EOMONTH(E3,-12) -> 45596 | F2: =EOMONTH(F3,-12) -> 45626 | G2: =EOMONTH(G3,-12) -> 45657 | H2: =EOMONTH(H3,-12) -> 45688 | I2: =EOMONTH(I3,-12) -> 45716 | J2: =EOMONTH(J3,-12) -> 45747 | ... N2: =EOMONTH(N3,-12) -> 45869
B3: End Date | C3: =EOMONTH(D3,-1) -> 45900 | D3: =EOMONTH(E3,-1) -> 45930 | E3: =EOMONTH(F3,-1) -> 45961 | F3: =EOMONTH(G3,-1) -> 45991 | G3: =EOMONTH(H3,-1) -> 46022 | H3: =EOMONTH(I3,-1) -> 46053 | I3: =EOMONTH(J3,-1) -> 46081 | J3: =EOMONTH(K3,-1) -> 46112 | ... M3: =EOMONTH(N3,-1) -> 46203 | N3: {=INDEX('Index Levels'!A3:A1048576,COUNT('Index Levels'!A3:A1048576),0)} -> 46234
C5: =TEXT(C3,"mmm")&". "&TEXT(C3,"yyyy") -> Aug. 2025 | D5: =TEXT(D3,"mmm")&". "&TEXT(D3,"yyyy") -> Sep. 2025 | E5: =TEXT(E3,"mmm")&". "&TEXT(E3,"yyyy") -> Oct. 2025 | F5: =TEXT(F3,"mmm")&". "&TEXT(F3,"yyyy") -> Nov. 2025 | G5: =TEXT(G3,"mmm")&". "&TEXT(G3,"yyyy") -> Dec. 2025 | H5: =TEXT(H3,"mmm")&". "&TEXT(H3,"yyyy") -> Jan. 2026 | I5: =TEXT(I3,"mmm")&". "&TEXT(I3,"yyyy") -> Feb. 2026 | J5: =TEXT(J3,"mmm")&". "&TEXT(J3,"yyyy") -> Mar. 2026 | ... N5: =TEXT(N3,"mmm")&". "&TEXT(N3,"yyyy") -> Jul. 2026
B6: S&P 500 FC TCA 0.50% Decrement Index ER | C6: =INDEX('Index Levels - Full'!$B:$B,MATCH('12 Month Rolling Return'!C$3,'Index Levels - Full'!$A:$A,0))/INDEX('Index Levels - Full'!$B:$B,MATCH('12 Month Rolling Return'!C$2,'Index Levels - Full'!$A:$A,0))-1 -> 0.0077591245 | D6: =INDEX('Index Levels - Full'!$B:$B,MATCH('12 Month Rolling Return'!D$3,'Index Levels - Full'!$A:$A,0))/INDEX('Index Levels - Full'!$B:$B,MATCH('12 Month Rolling Return'!D$2,'Index Levels - Full'!$A:$A,0))-1 -> 0.032831679 | E6: =INDEX('Index Levels - Full'!$B:$B,MATCH('12 Month Rolling Return'!E$3,'Index Levels - Full'!$A:$A,0))/INDEX('Index Levels - Full'!$B:$B,MATCH('12 Month Rolling Return'!E$2,'Index Levels - Full'!$A:$A,0))-1 -> 0.051304028 | F6: =INDEX('Index Levels - Full'!$B:$B,MATCH('12 Month Rolling Return'!F$3,'Index Levels - Full'!$A:$A,0))/INDEX('Index Levels - Full'!$B:$B,MATCH('12 Month Rolling Return'!F$2,'Index Levels - Full'!$A:$A,0))-1 -> -0.02144005 | G6: =INDEX('Index Levels - Full'!$B:$B,MATCH('12 Month Rolling Return'!G$3,'Index Levels - Full'!$A:$A,0))/INDEX('Index Levels - Full'!$B:$B,MATCH('12 Month Rolling Return'!G$2,'Index Levels - Full'!$A:$A,0))-1 -> 0.0159889 | H6: =INDEX('Index Levels - Full'!$B:$B,MATCH('12 Month Rolling Return'!H$3,'Index Levels - Full'!$A:$A,0))/INDEX('Index Levels - Full'!$B:$B,MATCH('12 Month Rolling Return'!H$2,'Index Levels - Full'!$A:$A,0))-1 -> 0.0097088733 | I6: =INDEX('Index Levels - Full'!$B:$B,MATCH('12 Month Rolling Return'!I$3,'Index Levels - Full'!$A:$A,0))/INDEX('Index Levels - Full'!$B:$B,MATCH('12 Month Rolling Return'!I$2,'Index Levels - Full'!$A:$A,0))-1 -> 0.021996138 | J6: =INDEX('Index Levels - Full'!$B:$B,MATCH('12 Month Rolling Return'!J$3,'Index Levels - Full'!$A:$A,0))/INDEX('Index Levels - Full'!$B:$B,MATCH('12 Month Rolling Return'!J$2,'Index Levels - Full'!$A:$A,0))-1 -> 0.0081577105 | ... N6: =INDEX('Index Levels - Full'!$B:$B,MATCH('12 Month Rolling Return'!N$3,'Index Levels - Full'!$A:$A,0))/INDEX('Index Levels - Full'!$B:$B,MATCH('12 Month Rolling Return'!N$2,'Index Levels - Full'!$A:$A,0))-1 -> -0.0099443632
B7: S&P 500 | C7: =INDEX('Index Levels - Full'!$C:$C,MATCH('12 Month Rolling Return'!C$3,'Index Levels - Full'!$A:$A,0))/INDEX('Index Levels - Full'!$C:$C,MATCH('12 Month Rolling Return'!C$2,'Index Levels - Full'!$A:$A,0))-1 -> 0.14373377 | D7: =INDEX('Index Levels - Full'!$C:$C,MATCH('12 Month Rolling Return'!D$3,'Index Levels - Full'!$A:$A,0))/INDEX('Index Levels - Full'!$C:$C,MATCH('12 Month Rolling Return'!D$2,'Index Levels - Full'!$A:$A,0))-1 -> 0.16069008 | E7: =INDEX('Index Levels - Full'!$C:$C,MATCH('12 Month Rolling Return'!E$3,'Index Levels - Full'!$A:$A,0))/INDEX('Index Levels - Full'!$C:$C,MATCH('12 Month Rolling Return'!E$2,'Index Levels - Full'!$A:$A,0))-1 -> 0.198889 | F7: =INDEX('Index Levels - Full'!$C:$C,MATCH('12 Month Rolling Return'!F$3,'Index Levels - Full'!$A:$A,0))/INDEX('Index Levels - Full'!$C:$C,MATCH('12 Month Rolling Return'!F$2,'Index Levels - Full'!$A:$A,0))-1 -> 0.13538643 | G7: =INDEX('Index Levels - Full'!$C:$C,MATCH('12 Month Rolling Return'!G$3,'Index Levels - Full'!$A:$A,0))/INDEX('Index Levels - Full'!$C:$C,MATCH('12 Month Rolling Return'!G$2,'Index Levels - Full'!$A:$A,0))-1 -> 0.16387931 | H7: =INDEX('Index Levels - Full'!$C:$C,MATCH('12 Month Rolling Return'!H$3,'Index Levels - Full'!$A:$A,0))/INDEX('Index Levels - Full'!$C:$C,MATCH('12 Month Rolling Return'!H$2,'Index Levels - Full'!$A:$A,0))-1 -> 0.14874592 | I7: =INDEX('Index Levels - Full'!$C:$C,MATCH('12 Month Rolling Return'!I$3,'Index Levels - Full'!$A:$A,0))/INDEX('Index Levels - Full'!$C:$C,MATCH('12 Month Rolling Return'!I$2,'Index Levels - Full'!$A:$A,0))-1 -> 0.15523939 | J7: =INDEX('Index Levels - Full'!$C:$C,MATCH('12 Month Rolling Return'!J$3,'Index Levels - Full'!$A:$A,0))/INDEX('Index Levels - Full'!$C:$C,MATCH('12 Month Rolling Return'!J$2,'Index Levels - Full'!$A:$A,0))-1 -> 0.16334441 | ... N7: =INDEX('Index Levels - Full'!$C:$C,MATCH('12 Month Rolling Return'!N$3,'Index Levels - Full'!$A:$A,0))/INDEX('Index Levels - Full'!$C:$C,MATCH('12 Month Rolling Return'!N$2,'Index Levels - Full'!$A:$A,0))-1 -> 0.18145743

Sheet Asset Class Exposures
A1: File Location | B1: S:\IndexReports\Standard\Options\500 FC TCA Index
F2: Monthly Average | J2: End of Month
A3: Date | B3: Month | C3: Equity | D3: Cash | G3: Equities | H3: Cash | L3: Equities | M3: Cash
A4: ='Index Levels'!A1092 -> 45870 | B4: =TEXT(MONTH(A4)*29,"mmmm") -> August | C4: 0.24362167 | D4: =IF(C4>1,0,1-C4) -> 0.75637833 | F4: {=_xlfn.IFS(F5="August","July",F5="July","June",F5="June","May",F5="May","April",F5="April","March",F5="March","February",F5="February","January",F5="January","December",F5="December","November",F5="November","October",F5="October","September",F5="September","August")} -> August | G4: =AVERAGEIF($B:$B,"*"&$F4&"*",$C:$C) -> 0.99814855 | H4: =AVERAGEIF($B:$B,"*"&$F4&"*",D:D) -> 0.10578172 | I4: =RANK(G4,$G$4:$G$15,0) -> 5 | J4: {=MAX(IF(B:B=F4,A:A))} -> 45898 | K4: =TEXT(J4,"mmm")&". "&YEAR(J4) -> Aug. 2025 | L4: =INDEX(C:C,MATCH($J4,$A:$A,0)) -> 1.3152958 | M4: =INDEX(D:D,MATCH($J4,$A:$A,0)) -> 0
A5: ='Index Levels'!A1093 -> 45873 | B5: =TEXT(MONTH(A5)*29,"mmmm") -> August | C5: 0.6104369 | D5: =IF(C5>1,0,1-C5) -> 0.3895631 | F5: {=_xlfn.IFS(F6="August","July",F6="July","June",F6="June","May",F6="May","April",F6="April","March",F6="March","February",F6="February","January",F6="January","December",F6="December","November",F6="November","October",F6="October","September",F6="September","August")} -> September | G5: =AVERAGEIF($B:$B,"*"&$F5&"*",$C:$C) -> 1.2666352 | H5: =AVERAGEIF($B:$B,"*"&$F5&"*",D:D) -> 0.0071530144 | I5: =RANK(G5,$G$4:$G$15,0) -> 1 | J5: {=MAX(IF(B:B=F5,A:A))} -> 45930 | K5: =TEXT(J5,"mmm")&". "&YEAR(J5) -> Sep. 2025 | L5: =INDEX(C:C,MATCH($J5,$A:$A,0)) -> 1.2323654 | M5: =INDEX(D:D,MATCH($J5,$A:$A,0)) -> 0
A6: ='Index Levels'!A1094 -> 45874 | B6: =TEXT(MONTH(A6)*29,"mmmm") -> August | C6: 0.63740794 | D6: =IF(C6>1,0,1-C6) -> 0.36259206 | F6: {=_xlfn.IFS(F7="August","July",F7="July","June",F7="June","May",F7="May","April",F7="April","March",F7="March","February",F7="February","January",F7="January","December",F7="December","November",F7="November","October",F7="October","September",F7="September","August")} -> October | G6: =AVERAGEIF($B:$B,"*"&$F6&"*",$C:$C) -> 0.95211856 | H6: =AVERAGEIF($B:$B,"*"&$F6&"*",D:D) -> 0.19884201 | I6: =RANK(G6,$G$4:$G$15,0) -> 7 | J6: {=MAX(IF(B:B=F6,A:A))} -> 45961 | K6: =TEXT(J6,"mmm")&". "&YEAR(J6) -> Oct. 2025 | L6: =INDEX(C:C,MATCH($J6,$A:$A,0)) -> 0.96994943 | M6: =INDEX(D:D,MATCH($J6,$A:$A,0)) -> 0.030050571
A7: ='Index Levels'!A1095 -> 45875 | B7: =TEXT(MONTH(A7)*29,"mmmm") -> August | C7: 0.75477355 | D7: =IF(C7>1,0,1-C7) -> 0.24522645 | F7: {=_xlfn.IFS(F8="August","July",F8="July","June",F8="June","May",F8="May","April",F8="April","March",F8="March","February",F8="February","January",F8="January","December",F8="December","November",F8="November","October",F8="October","September",F8="September","August")} -> November | G7: =AVERAGEIF($B:$B,"*"&$F7&"*",$C:$C) -> 0.73762359 | H7: =AVERAGEIF($B:$B,"*"&$F7&"*",D:D) -> 0.26961676 | I7: =RANK(G7,$G$4:$G$15,0) -> 11 | J7: {=MAX(IF(B:B=F7,A:A))} -> 45989 | K7: =TEXT(J7,"mmm")&". "&YEAR(J7) -> Nov. 2025 | L7: =INDEX(C:C,MATCH($J7,$A:$A,0)) -> 0.6083575 | M7: =INDEX(D:D,MATCH($J7,$A:$A,0)) -> 0.3916425
A8: ='Index Levels'!A1096 -> 45876 | B8: =TEXT(MONTH(A8)*29,"mmmm") -> August | C8: 0.83435202 | D8: =IF(C8>1,0,1-C8) -> 0.16564798 | F8: {=_xlfn.IFS(F9="August","July",F9="July","June",F9="June","May",F9="May","April",F9="April","March",F9="March","February",F9="February","January",F9="January","December",F9="December","November",F9="November","October",F9="October","September",F9="September","August")} -> December | G8: =AVERAGEIF($B:$B,"*"&$F8&"*",$C:$C) -> 1.1437936 | H8: =AVERAGEIF($B:$B,"*"&$F8&"*",D:D) -> 0.047761848 | I8: =RANK(G8,$G$4:$G$15,0) -> 2 | J8: {=MAX(IF(B:B=F8,A:A))} -> 46022 | K8: =TEXT(J8,"mmm")&". "&YEAR(J8) -> Dec. 2025 | L8: =INDEX(C:C,MATCH($J8,$A:$A,0)) -> 1.6929365 | M8: =INDEX(D:D,MATCH($J8,$A:$A,0)) -> 0
A9: ='Index Levels'!A1097 -> 45877 | B9: =TEXT(MONTH(A9)*29,"mmmm") -> August | C9: 0.84458892 | D9: =IF(C9>1,0,1-C9) -> 0.15541108 | F9: {=_xlfn.IFS(F10="August","July",F10="July","June",F10="June","May",F10="May","April",F10="April","March",F10="March","February",F10="February","January",F10="January","December",F10="December","November",F10="November","October",F10="October","September",F10="September","August")} -> January | G9: =AVERAGEIF($B:$B,"*"&$F9&"*",$C:$C) -> 1.1061201 | H9: =AVERAGEIF($B:$B,"*"&$F9&"*",D:D) -> 0.12020686 | I9: =RANK(G9,$G$4:$G$15,0) -> 3 | J9: {=MAX(IF(B:B=F9,A:A))} -> 46052 | K9: =TEXT(J9,"mmm")&". "&YEAR(J9) -> Jan. 2026 | L9: =INDEX(C:C,MATCH($J9,$A:$A,0)) -> 0.84336196 | M9: =INDEX(D:D,MATCH($J9,$A:$A,0)) -> 0.15663804
A10: ='Index Levels'!A1098 -> 45880 | B10: =TEXT(MONTH(A10)*29,"mmmm") -> August | C10: 0.96316342 | D10: =IF(C10>1,0,1-C10) -> 0.036836578 | F10: {=_xlfn.IFS(F11="August","July",F11="July","June",F11="June","May",F11="May","April",F11="April","March",F11="March","February",F11="February","January",F11="January","December",F11="December","November",F11="November","October",F11="October","September",F11="September","August")} -> February | G10: =AVERAGEIF($B:$B,"*"&$F10&"*",$C:$C) -> 0.82410586 | H10: =AVERAGEIF($B:$B,"*"&$F10&"*",D:D) -> 0.17589414 | I10: =RANK(G10,$G$4:$G$15,0) -> 8 | J10: {=MAX(IF(B:B=F10,A:A))} -> 46080 | K10: =TEXT(J10,"mmm")&". "&YEAR(J10) -> Feb. 2026 | L10: =INDEX(C:C,MATCH($J10,$A:$A,0)) -> 0.92257802 | M10: =INDEX(D:D,MATCH($J10,$A:$A,0)) -> 0.077421979
A11: ='Index Levels'!A1099 -> 45881 | B11: =TEXT(MONTH(A11)*29,"mmmm") -> August | C11: 0.98772617 | D11: =IF(C11>1,0,1-C11) -> 0.012273828 | F11: {=_xlfn.IFS(F12="August","July",F12="July","June",F12="June","May",F12="May","April",F12="April","March",F12="March","February",F12="February","January",F12="January","December",F12="December","November",F12="November","October",F12="October","September",F12="September","August")} -> March | G11: =AVERAGEIF($B:$B,"*"&$F11&"*",$C:$C) -> 0.59937049 | H11: =AVERAGEIF($B:$B,"*"&$F11&"*",D:D) -> 0.40062951 | I11: =RANK(G11,$G$4:$G$15,0) -> 12 | J11: {=MAX(IF(B:B=F11,A:A))} -> 46112 | K11: =TEXT(J11,"mmm")&". "&YEAR(J11) -> Mar. 2026 | L11: =INDEX(C:C,MATCH($J11,$A:$A,0)) -> 0.76354447 | M11: =INDEX(D:D,MATCH($J11,$A:$A,0)) -> 0.23645553
A12: ='Index Levels'!A1100 -> 45882 | B12: =TEXT(MONTH(A12)*29,"mmmm") -> August | C12: 1.0005434 | D12: =IF(C12>1,0,1-C12) -> 0 | F12: {=_xlfn.IFS(F13="August","July",F13="July","June",F13="June","May",F13="May","April",F13="April","March",F13="March","February",F13="February","January",F13="January","December",F13="December","November",F13="November","October",F13="October","September",F13="September","August")} -> April | G12: =AVERAGEIF($B:$B,"*"&$F12&"*",$C:$C) -> 0.77753211 | H12: =AVERAGEIF($B:$B,"*"&$F12&"*",D:D) -> 0.23772129 | I12: =RANK(G12,$G$4:$G$15,0) -> 9 | J12: {=MAX(IF(B:B=F12,A:A))} -> 46142 | K12: =TEXT(J12,"mmm")&". "&YEAR(J12) -> Apr. 2026 | L12: =INDEX(C:C,MATCH($J12,$A:$A,0)) -> 1.1692219 | M12: =INDEX(D:D,MATCH($J12,$A:$A,0)) -> 0
A13: ='Index Levels'!A1101 -> 45883 | B13: =TEXT(MONTH(A13)*29,"mmmm") -> August | C13: 1.0970355 | D13: =IF(C13>1,0,1-C13) -> 0 | F13: {=_xlfn.IFS(F14="August","July",F14="July","June",F14="June","May",F14="May","April",F14="April","March",F14="March","February",F14="February","January",F14="January","December",F14="December","November",F14="November","October",F14="October","September",F14="September","August")} -> May | G13: =AVERAGEIF($B:$B,"*"&$F13&"*",$C:$C) -> 1.0482862 | H13: =AVERAGEIF($B:$B,"*"&$F13&"*",D:D) -> 0.035560257 | I13: =RANK(G13,$G$4:$G$15,0) -> 4 | J13: {=MAX(IF(B:B=F13,A:A))} -> 46171 | K13: =TEXT(J13,"mmm")&". "&YEAR(J13) -> May. 2026 | L13: =INDEX(C:C,MATCH($J13,$A:$A,0)) -> 1.1055989 | M13: =INDEX(D:D,MATCH($J13,$A:$A,0)) -> 0
A14: ='Index Levels'!A1102 -> 45884 | B14: =TEXT(MONTH(A14)*29,"mmmm") -> August | C14: 1.2102612 | D14: =IF(C14>1,0,1-C14) -> 0 | F14: {=_xlfn.IFS(F15="August","July",F15="July","June",F15="June","May",F15="May","April",F15="April","March",F15="March","February",F15="February","January",F15="January","December",F15="December","November",F15="November","October",F15="October","September",F15="September","August")} -> June | G14: =AVERAGEIF($B:$B,"*"&$F14&"*",$C:$C) -> 0.76795396 | H14: =AVERAGEIF($B:$B,"*"&$F14&"*",D:D) -> 0.28484901 | I14: =RANK(G14,$G$4:$G$15,0) -> 10 | J14: {=MAX(IF(B:B=F14,A:A))} -> 46203 | K14: =TEXT(J14,"mmm")&". "&YEAR(J14) -> Jun. 2026 | L14: =INDEX(C:C,MATCH($J14,$A:$A,0)) -> 0.81344901 | M14: =INDEX(D:D,MATCH($J14,$A:$A,0)) -> 0.18655099
A15: ='Index Levels'!A1103 -> 45887 | B15: =TEXT(MONTH(A15)*29,"mmmm") -> August | C15: 1.3436339 | D15: =IF(C15>1,0,1-C15) -> 0 | F15: {=TEXT(INDEX(A4:A290,COUNTA(A4:A290)),"mmmm")} -> July | G15: =AVERAGEIF($B:$B,"*"&$F15&"*",$C:$C) -> 0.97237815 | H15: =AVERAGEIF($B:$B,"*"&$F15&"*",D:D) -> 0.095170869 | I15: =RANK(G15,$G$4:$G$15,0) -> 6 | J15: {=MAX(IF(B:B=F15,A:A))} -> 46234 | K15: =TEXT(J15,"mmm")&". "&YEAR(J15) -> Jul. 2026 | L15: =INDEX(C:C,MATCH($J15,$A:$A,0)) -> 0.61270038 | M15: =INDEX(D:D,MATCH($J15,$A:$A,0)) -> 0.38729962
A16: ='Index Levels'!A1104 -> 45888 | B16: =TEXT(MONTH(A16)*29,"mmmm") -> August | C16: 1.4398855 | D16: =IF(C16>1,0,1-C16) -> 0
A17: ='Index Levels'!A1105 -> 45889 | B17: =TEXT(MONTH(A17)*29,"mmmm") -> August | C17: 1.2026383 | D17: =IF(C17>1,0,1-C17) -> 0 | F17: {=TEXT((INDEX(A4:A99291,COUNT(A4:A99291),0)),"mmmm")&" "&YEAR(INDEX(A4:A99291,COUNT(A4:A99291),0))&" Average"} -> July 2026 Average | J17: {=TEXT((INDEX(A4:A99291,COUNT(A4:A99291),0)),"mmmm")&" "&YEAR(INDEX(A4:A99291,COUNT(A4:A99291),0))&" End of Month"} -> July 2026 End of Month
A18: ='Index Levels'!A1106 -> 45890 | B18: =TEXT(MONTH(A18)*29,"mmmm") -> August | C18: 1.2007173 | D18: =IF(C18>1,0,1-C18) -> 0 | F18: Equities | G18: Cash | H18: Total | K18: Equities | L18: Cash | M18: Total
A19: ='Index Levels'!A1107 -> 45891 | B19: =TEXT(MONTH(A19)*29,"mmmm") -> August | C19: 0.97478729 | D19: =IF(C19>1,0,1-C19) -> 0.025212709 | F19: =G15 -> 0.97237815 | G19: =H15 -> 0.095170869 | H19: =SUM(F19:G19) -> 1.067549 | K19: {=INDEX(C4:C9479,COUNT(C4:C99479),0)} -> 0.61270038 | L19: {=INDEX(D4:D9291,COUNT(D4:D99291),0)} -> 0.38729962 | M19: =SUM(K19:L19) -> 1
A20: ='Index Levels'!A1108 -> 45894 | B20: =TEXT(MONTH(A20)*29,"mmmm") -> August | C20: 0.92772591 | D20: =IF(C20>1,0,1-C20) -> 0.072274095
A21: ='Index Levels'!A1109 -> 45895 | B21: =TEXT(MONTH(A21)*29,"mmmm") -> August | C21: 1.0227554 | D21: =IF(C21>1,0,1-C21) -> 0 | F21: 12 Month Average
A22: ='Index Levels'!A1110 -> 45896 | B22: =TEXT(MONTH(A22)*29,"mmmm") -> August | C22: 1.1214596 | D22: =IF(C22>1,0,1-C22) -> 0 | F22: Equities | G22: Cash | H22: Total
A23: ='Index Levels'!A1111 -> 45897 | B23: =TEXT(MONTH(A23)*29,"mmmm") -> August | C23: 1.2283097 | D23: =IF(C23>1,0,1-C23) -> 0 | F23: =AVERAGE(C:C) -> 0.9339335 | G23: =AVERAGE(D:D) -> 0.16516889 | H23: =SUM(F23:G23) -> 1.0991024
A24: ='Index Levels'!A1112 -> 45898 | B24: =TEXT(MONTH(A24)*29,"mmmm") -> August | C24: 1.3152958 | D24: =IF(C24>1,0,1-C24) -> 0
A25: ='Index Levels'!A1113 -> 45902 | B25: =TEXT(MONTH(A25)*29,"mmmm") -> September | C25: 0.99164558 | D25: =IF(C25>1,0,1-C25) -> 0.0083544167
A26: ='Index Levels'!A1114 -> 45903 | B26: =TEXT(MONTH(A26)*29,"mmmm") -> September | C26: 1.0759459 | D26: =IF(C26>1,0,1-C26) -> 0
A27: ='Index Levels'!A1115 -> 45904 | B27: =TEXT(MONTH(A27)*29,"mmmm") -> September | C27: 1.192364 | D27: =IF(C27>1,0,1-C27) -> 0
A28: ='Index Levels'!A1116 -> 45905 | B28: =TEXT(MONTH(A28)*29,"mmmm") -> September | C28: 0.86822376 | D28: =IF(C28>1,0,1-C28) -> 0.13177624
A29: ='Index Levels'!A1117 -> 45908 | B29: =TEXT(MONTH(A29)*29,"mmmm") -> September | C29: 1.0394381 | D29: =IF(C29>1,0,1-C29) -> 0
A30: ='Index Levels'!A1118 -> 45909 | B30: =TEXT(MONTH(A30)*29,"mmmm") -> September | C30: 1.1551657 | D30: =IF(C30>1,0,1-C30) -> 0
A31: ='Index Levels'!A1119 -> 45910 | B31: =TEXT(MONTH(A31)*29,"mmmm") -> September | C31: 1.1871527 | D31: =IF(C31>1,0,1-C31) -> 0
A32: ='Index Levels'!A1120 -> 45911 | B32: =TEXT(MONTH(A32)*29,"mmmm") -> September | C32: 1.237496 | D32: =IF(C32>1,0,1-C32) -> 0
A33: ='Index Levels'!A1121 -> 45912 | B33: =TEXT(MONTH(A33)*29,"mmmm") -> September | C33: 1.3763869 | D33: =IF(C33>1,0,1-C33) -> 0
A34: ='Index Levels'!A1122 -> 45915 | B34: =TEXT(MONTH(A34)*29,"mmmm") -> September | C34: 1.4569549 | D34: =IF(C34>1,0,1-C34) -> 0
A35: ='Index Levels'!A1123 -> 45916 | B35: =TEXT(MONTH(A35)*29,"mmmm") -> September | C35: 1.6065856 | D35: =IF(C35>1,0,1-C35) -> 0
... A148: ='Index Levels'!A1236 -> 46080 | B148: =TEXT(MONTH(A148)*29,"mmmm") -> February | C148: 0.92257802 | D148: =IF(C148>1,0,1-C148) -> 0.077421979
A149: ='Index Levels'!A1237 -> 46083 | B149: =TEXT(MONTH(A149)*29,"mmmm") -> March | C149: 0.91765681 | D149: =IF(C149>1,0,1-C149) -> 0.082343189 | E149: X
A150: ='Index Levels'!A1238 -> 46084 | B150: =TEXT(MONTH(A150)*29,"mmmm") -> March | C150: 0.44346359 | D150: =IF(C150>1,0,1-C150) -> 0.55653641
A151: ='Index Levels'!A1239 -> 46085 | B151: =TEXT(MONTH(A151)*29,"mmmm") -> March | C151: 0.52390754 | D151: =IF(C151>1,0,1-C151) -> 0.47609246
A152: ='Index Levels'!A1240 -> 46086 | B152: =TEXT(MONTH(A152)*29,"mmmm") -> March | C152: 0.58838243 | D152: =IF(C152>1,0,1-C152) -> 0.41161757
...

Sheet Calc 
A1: DATE | B1: ISROLLDATE | C1: IS_PARTIAL | D1: RIC | E1: CYCLE | F1: FutTWAP | G1: ROLL_IN | H1: ROLL_IN_TWAP | I1: SPXFP | J1: FFR | K1: 500TR | L1: SPTWAP | M1: EQ_intraday | N1: ROLL_FUT_IDX_LAST | O1: VIX_LAG | P1: SPTR_TWAP | Q1: ES_TWAP_RATIO | R1: ROLL_FUT_IDX | S1: FINAN_FEE | T1: FINAN_FEE_FOR_CALC | U1: EQ_VOL_ST | V1: EQ_VOL_LT | W1: EQ_VOL | X1: Delta | Y1: DAILY_120D_VOL | Z1: DAILY_120D_VOL_FOR_VAF | AA1: INTRADAY_21D_VOL | AB1: PARTICIPATION | AC1: FCVHL_RET | AD1: FCVHL_1 | AE1: FCVHL | AF1: INDEX_LEVEL | AG1: INDEX_LEVEL_1 | AH1: DATE_FOR_FT | AI1: EQ_LOGRET | AJ1: EQ_LAST_LVL | AK1: EQ_LVL_FOR_STRIKE | AL1: Call_strike | AM1: Put_strike | AN1: ITTE | AO1: ITTE_DELTA | AP1: VOL_FOR_DELTA | AQ1: Delta_Call | AR1: Delta_Put | AS1: DAILY_120D_VAF | AT1: INTRADAY_21D_VAF | AU1: VAF | AV1: TARGET_PARTICIPATION
A2: 45566 | B2: FALSE | C2: FALSE | D2: 2024ESZ | E2: C1 | F2: 5765.175 | H2: 0 | I2: 488.06552 | J2: 0.0483 | K2: 12490.872 | L2: 12501.521 | M2: 461.24197 | O2: 16.73 | P2: 12501.521 | Q2: 0.99171944 | T2: 0.057439256 | U2: 0.11296447 | V2: 0.10977371 | W2: 0.11296447 | X2: -0.069264198 | Z2: 0.10749124 | AA2: 0.11725005 | AB2: 1.2353789 | AC2: -0.010589899 | AD2: 491.5148 | AE2: 486.30971 | AG2: 491.5148 | AI2: 6.3056296e-05 | AK2: 464.91918 | AL2: 471.89297 | AM2: 457.94539 | AN2: 0.0010058422 | AO2: 0.00084049824 | AP2: 0.1673 | AQ2: 1.2729114e-06 | AR2: -0.069265471 | AS2: 1.0612841 | AT2: 1.0181423 | AU2: 1.0181423 | AV2: 1.2353789
A3: 45566 | B3: FALSE | C3: FALSE | D3: 2024ESZ | E3: C2 | F3: 5752.7875 | H3: 0 | I3: 488.06552 | J3: 0.0483 | K3: 12490.872 | L3: 12474.495 | M3: 460.24485 | O3: 16.73 | P3: 12474.495 | Q3: 0.99785132 | T3: 0.057439256 | U3: 0.11176324 | V3: 0.10925481 | W3: 0.11176324 | X3: -0.12417458 | Z3: 0.10749124 | AA3: 0.11760953 | AB3: 0.98537893 | AC3: -0.0026956631 | AD3: 491.5148 | AE3: 484.99878 | AG3: 491.5148 | AI3: 4.6835757e-06 | AK3: 464.91918 | AL3: 471.89297 | AM3: 457.94539 | AN3: 0.00084049824 | AO3: 0.00067515432 | AP3: 0.1673 | AQ3: 4.533019e-09 | AR3: -0.12417458 | AS3: 1.0612841 | AT3: 0.98004385 | AU3: 0.98004385 | AV3: 0.92786425
A4: 45566 | B4: FALSE | C4: FALSE | D4: 2024ESZ | E4: C3 | F4: 5761.05 | H4: 0 | I4: 488.06552 | J4: 0.0483 | K4: 12490.872 | L4: 12491.565 | M4: 460.87464 | O4: 16.73 | P4: 12491.565 | Q4: 1.0014363 | T4: 0.057439256 | U4: 0.1092679 | V4: 0.10806235 | W4: 0.1092679 | X4: -0.04553021 | Z4: 0.10749124 | AA4: 0.11690751 | AB4: 0.88446146 | AC4: 0.001338293 | AD4: 491.5148 | AE4: 485.64785 | AG4: 491.5148 | AI4: 1.8699377e-06 | AK4: 464.91918 | AL4: 471.89297 | AM4: 457.94539 | AN4: 0.00067515432 | AO4: 0.00050981041 | AP4: 0.1673 | AQ4: 2.0183454e-10 | AR4: -0.04553021 | AS4: 1.0612841 | AT4: 0.97678142 | AU4: 0.97678142 | AV4: 0.88446146
A5: 45566 | B5: FALSE | C5: FALSE | D5: 2024ESZ | E5: C4 | F5: 5748.3 | H5: 0 | I5: 488.06552 | J5: 0.0483 | K5: 12490.872 | L5: 12464.412 | M5: 459.87284 | O5: 16.73 | P5: 12464.412 | Q5: 0.99778686 | T5: 0.057439256 | U5: 0.10827876 | V5: 0.1075999 | W5: 0.10827876 | X5: -0.087835308 | Z5: 0.10749124 | AA5: 0.1170209 | AB5: 0.98297203 | AC5: -0.001932411 | AD5: 491.5148 | AE5: 484.70938 | AG5: 491.5148 | AI5: 4.7352926e-06 | AK5: 464.91918 | AL5: 471.89297 | AM5: 457.94539 | AN5: 0.00050981041 | AO5: 0.00034446649 | AP5: 0.1673 | AQ5: 4.8590437e-17 | AR5: -0.087835308 | AS5: 1.0612841 | AT5: 0.98313313 | AU5: 0.98313313 | AV5: 0.98297203
A6: 45566 | B6: FALSE | C6: FALSE | D6: 2024ESZ | E6: C5 | F6: 5754.775 | H6: 0 | I6: 488.06552 | J6: 0.0483 | K6: 12490.872 | L6: 12475.933 | M6: 460.2979 | O6: 16.73 | P6: 12475.933 | Q6: 1.0011264 | T6: 0.057439256 | U6: 0.10540955 | V6: 0.10618652 | W6: 0.10618652 | X6: -0.011024312 | Z6: 0.10749124 | AA6: 0.11697493 | AB6: 0.94919887 | AC6: 0.00090519509 | AD6: 491.5148 | AE6: 485.14814 | AG6: 491.5148 | AI6: 8.5356283e-07 | AK6: 464.91918 | AL6: 471.89297 | AM6: 457.94539 | AN6: 0.00034446649 | AO6: 0.00017912257 | AP6: 0.1673 | AQ6: 5.6211893e-29 | AR6: -0.011024312 | AS6: 1.0612841 | AT6: 0.98211254 | AU6: 0.98211254 | AV6: 0.94919887
A7: 45566 | B7: FALSE | C7: FALSE | D7: 2024ESZ | E7: C6 | F7: 5777.175 | H7: 0 | I7: 488.06552 | J7: 0.0483 | K7: 12490.872 | L7: 12524.803 | M7: 462.10096 | O7: 16.73 | P7: 12524.803 | Q7: 1.0038924 | T7: 0.057439256 | U7: 0.10982793 | V7: 0.10837964 | W7: 0.10982793 | X7: 0 | Z7: 0.10749124 | AA7: 0.11737608 | AB7: 1.0534355 | AC7: 0.003707723 | AD7: 491.5148 | AE7: 486.94693 | AG7: 491.5148 | AI7: 1.5284111e-05 | AK7: 464.91918 | AL7: 471.89297 | AM7: 457.94539 | AN7: 0.00017912257 | AO7: 0 | AP7: 0.1673 | AQ7: 0 | AR7: 0 | AS7: 1.0612841 | AT7: 0.9825266 | AU7: 0.9825266 | AV7: 1.0534355
A8: 45566 | B8: FALSE | C8: FALSE | D8: 2024ESZ | E8: C7 | F8: 5762.15 | G8: usual | H8: 0 | I8: 488.06552 | J8: 0.0483 | K8: 12490.872 | L8: 12493.091 | M8: 460.93095 | N8: 465.13237 | O8: 16.73 | P8: 12493.091 | Q8: 0.99739925 | R8: 465.13237 | S8: 0.067556415 | T8: 0.057439256 | U8: 0.10962971 | V8: 0.10832302 | W8: 0.10962971 | X8: 0 | Y8: 0.108659 | Z8: 0.10749124 | AA8: 0.11634042 | AB8: 1.0250014 | AC8: -0.0026700747 | AD8: 491.5148 | AE8: 485.64675 | AF8: 485.64675 | AG8: 491.5148 | AH8: 45566 | AI8: 6.4269693e-06 | AJ8: 460.93095 | AK8: 464.91918 | AL8: 471.89297 | AM8: 457.94539 | AN8: 0 | AO8: 0.0010058422 | AP8: 0.1673 | AQ8: 0 | AR8: 0 | AS8: 1.0612841 | AT8: 0.97890241 | AU8: 0.97890241 | AV8: 1.0250014
A9: 45567 | B9: FALSE | C9: FALSE | D9: 2024ESZ | E9: C1 | F9: 5741.45 | H9: 0 | I9: 488.10789 | J9: 0.0483 | K9: 12493.354 | L9: 12451.121 | M9: 459.29597 | O9: 19.26 | P9: 12451.121 | Q9: 0.99640759 | T9: 0.067556415 | U9: 0.11240095 | V9: 0.10977281 | W9: 0.11240095 | X9: -0.01859669 | Z9: 0.108659 | AA9: 0.113252 | AB9: 1.0366147 | AC9: -0.0036508465 | AD9: 485.64675 | AE9: 483.87372 | AG9: 485.64675 | AI9: 1.262679e-05 | AK9: 460.93095 | AL9: 467.84491 | AM9: 454.01698 | AN9: 0.0010058422 | AO9: 0.00084049824 | AP9: 0.1926 | AQ9: 0.00048338644 | AR9: -0.019080076 | AS9: 1.0522537 | AT9: 0.98820672 | AU9: 0.98820672 | AV9: 1.0366147
A10: 45567 | B10: FALSE | C10: FALSE | D10: 2024ESZ | E10: C2 | F10: 5761.25 | H10: 0 | I10: 488.10789 | J10: 0.0483 | K10: 12493.354 | L10: 12493.64 | M10: 460.86441 | O10: 19.26 | P10: 12493.64 | Q10: 1.0034486 | T10: 0.067556415 | U10: 0.11448131 | V10: 0.11092153 | W10: 0.11448131 | X10: -3.4487518e-05 | Z10: 0.108659 | AA10: 0.1121222 | AB10: 1.0176728 | AC10: 0.0035380137 | AD10: 485.64675 | AE10: 485.58568 | AG10: 485.64675 | AI10: 1.1621661e-05 | AK10: 460.93095 | AL10: 467.84491 | AM10: 454.01698 | AN10: 0.00084049824 | AO10: 0.00067515432 | AP10: 0.1926 | AQ10: 0.0013436647 | AR10: -0.0013781523 | AS10: 1.0522537 | AT10: 1.0149724 | AU10: 1.0149724 | AV10: 1.0176728
A11: 45567 | B11: FALSE | C11: FALSE | D11: 2024ESZ | E11: C3 | F11: 5769.5 | H11: 0 | I11: 488.10789 | J11: 0.0483 | K11: 12493.354 | L11: 12510.938 | M11: 461.5025 | O11: 19.26 | P11: 12510.938 | Q11: 1.001432 | T11: 0.067556415 | U11: 0.11190274 | V11: 0.10970772 | W11: 0.11190274 | X11: 0.00077066445 | Z11: 0.108659 | AA11: 0.11220792 | AB11: 1.0290546 | AC11: 0.0014078751 | AD11: 485.64675 | AE11: 486.26932 | AG11: 485.64675 | AI11: 1.9143126e-06 | AK11: 460.93095 | AL11: 467.84491 | AM11: 454.01698 | AN11: 0.00067515432 | AO11: 0.00050981041 | AP11: 0.1926 | AQ11: 0.0008547538 | AR11: -8.4089349e-05 | AS11: 1.0522537 | AT11: 1.0244132 | AU11: 1.0244132 | AV11: 1.0290546
A12: 45567 | B12: FALSE | C12: FALSE | D12: 2024ESZ | E12: C4 | F12: 5759.3375 | H12: 0 | I12: 488.10789 | J12: 0.0483 | K12: 12493.354 | L12: 12489.661 | M12: 460.71763 | O12: 19.26 | P12: 12489.661 | Q12: 0.99823858 | T12: 0.067556415 | U12: 0.10989782 | V12: 0.10875675 | W12: 0.10989782 | X12: -1.1806012e-05 | Z12: 0.108659 | AA12: 0.11234531 | AB12: 1.0520375 | AC12: -0.0017523825 | AD12: 485.64675 | AE12: 485.41719 | AG12: 485.64675 | AI12: 2.8972112e-06 | AK12: 460.93095 | AL12: 467.84491 | AM12: 454.01698 | AN12: 0.00050981041 | AO12: 0.00034446649 | AP12: 0.1926 | AQ12: 8.821751e-06 | AR12: -2.0627763e-05 | AS12: 1.0522537 | AT12: 1.0237033 | AU12: 1.0237033 | AV12: 1.0520375
A13: 45567 | B13: FALSE | C13: FALSE | D13: 2024ESZ | E13: C5 | F13: 5759.7 | H13: 0 | I13: 488.10789 | J13: 0.0483 | K13: 12493.354 | L13: 12490.353 | M13: 460.74316 | O13: 19.26 | P13: 12490.353 | Q13: 1.0000629 | T13: 0.067556415 | U13: 0.10655141 | V13: 0.10711374 | W13: 0.10711374 | X13: -4.2784266e-09 | Z13: 0.108659 | AA13: 0.11234128 | AB13: 1.0700374 | AC13: 5.6489016e-05 | AD13: 485.64675 | AE13: 485.44461 | AG13: 485.64675 | AI13: 3.0696356e-09 | AK13: 460.93095 | AL13: 467.84491 | AM13: 454.01698 | AN13: 0.00034446649 | AO13: 0.00017912257 | AP13: 0.1926 | AQ13: 1.4896334e-09 | AR13: -5.76806e-09 | AS13: 1.0522537 | AT13: 1.0225633 | AU13: 1.0225633 | AV13: 1.0700374
A14: 45567 | B14: FALSE | C14: FALSE | D14: 2024ESZ | E14: C6 | F14: 5761.15 | H14: 0 | I14: 488.10789 | J14: 0.0483 | K14: 12493.354 | L14: 12493.73 | M14: 460.86773 | O14: 19.26 | P14: 12493.73 | Q14: 1.0002517 | T14: 0.067556415 | U14: 0.10334286 | V14: 0.10551312 | W14: 0.10551312 | X14: 0 | Z14: 0.108659 | AA14: 0.11229281 | AB14: 1.0978856 | AC14: 0.00028651976 | AD14: 485.64675 | AE14: 485.5837 | AG14: 485.64675 | AI14: 7.3079453e-08 | AK14: 460.93095 | AL14: 467.84491 | AM14: 454.01698 | AN14: 0.00017912257 | AO14: 0 | AP14: 0.1926 | AQ14: 0 | AR14: 0 | AS14: 1.0522537 | AT14: 1.0225968 | AU14: 1.0225968 | AV14: 1.0978856
A15: 45567 | B15: FALSE | C15: FALSE | D15: 2024ESZ | E15: C7 | F15: 5763.025 | G15: usual | H15: 0 | I15: 488.10789 | J15: 0.0483 | K15: 12493.354 | L15: 12498.193 | M15: 461.03236 | N15: 465.203 | O15: 19.26 | P15: 12498.193 | Q15: 1.0003255 | R15: 465.203 | S15: 0.065708187 | T15: 0.067556415 | U15: 0.10026197 | V15: 0.10395085 | W15: 0.10395085 | X15: 0 | Y15: 0.10835016 | Z15: 0.108659 | AA15: 0.11227536 | AB15: 1.1149789 | AC15: 0.00039047647 | AD15: 485.64675 | AE15: 485.77331 | AF15: 485.77331 | AG15: 485.64675 | AH15: 45567 | AI15: 1.2755998e-07 | AJ15: 461.03236 | AK15: 460.93095 | AL15: 467.84491 | AM15: 454.01698 | AN15: 0 | AO15: 0.0010058422 | AP15: 0.1926 | AQ15: 0 | AR15: 0 | AS15: 1.0522537 | AT15: 1.0229992 | AU15: 1.0229992 | AV15: 1.1149789
A16: 45568 | B16: FALSE | C16: FALSE | D16: 2024ESZ | E16: C1 | F16: 5742.8625 | H16: 0 | I16: 487.19697 | J16: 0.0483 | K16: 12472.387 | L16: 12456.027 | M16: 459.39279 | O16: 18.9 | P16: 12456.027 | Q16: 0.9965014 | T16: 0.065708187 | U16: 0.10388778 | V16: 0.10560911 | W16: 0.10560911 | X16: -0.017010178 | Z16: 0.10835016 | AA16: 0.11313166 | AB16: 1.1318961 | AC16: -0.0039807695 | AD16: 485.77331 | AE16: 483.83956 | AG16: 485.77331 | AI16: 1.2692326e-05 | AK16: 461.03236 | AL16: 467.94784 | AM16: 454.11687 | AN16: 0.0010058422 | AO16: 0.00084049824 | AP16: 0.189 | AQ16: 0.00038318241 | AR16: -0.017393361 | AS16: 1.0546591 | AT16: 1.023144 | AU16: 1.023144 | AV16: 1.1318961
A17: 45568 | B17: FALSE | C17: FALSE | D17: 2024ESZ | E17: C2 | F17: 5749.775 | H17: 0 | I17: 487.19697 | J17: 0.0483 | K17: 12472.387 | L17: 12471.329 | M17: 459.95715 | O17: 18.9 | P17: 12471.329 | Q17: 1.0012037 | T17: 0.065708187 | U17: 0.1015118 | V17: 0.10439565 | W17: 0.10439565 | X17: -0.0043710911 | Z17: 0.10835016 | AA17: 0.11316736 | AB17: 1.0842028 | AC17: 0.0013857443 | AD17: 485.77331 | AE17: 484.51004 | AG17: 485.77331 | AI17: 1.5073151e-06 | AK17: 461.03236 | AL17: 467.94784 | AM17: 454.11687 | AN17: 0.00084049824 | AO17: 0.00067515432 | AP17: 0.189 | AQ17: 0.00022853737 | AR17: -0.0045996285 | AS17: 1.0546591 | AT17: 1.0159866 | AU17: 1.0159866 | AV17: 1.0842028
A18: 45568 | B18: FALSE | C18: FALSE | D18: 2024ESZ | E18: C3 | F18: 5758.3375 | H18: 0 | I18: 487.19697 | J18: 0.0483 | K18: 12472.387 | L18: 12488.991 | M18: 460.60855 | O18: 18.9 | P18: 12488.991 | Q18: 1.0014892 | T18: 0.065708187 | U18: 0.099490418 | V18: 0.10333193 | W18: 0.10333193 | X18: -0.00033013713 | Z18: 0.10835016 | AA18: 0.11318775 | AB18: 1.1188578 | AC18: 0.0015319916 | AD18: 485.77331 | AE18: 485.2523 | AG18: 485.77331 | AI18: 2.0028093e-06 | AK18: 461.03236 | AL18: 467.94784 | AM18: 454.11687 | AN18: 0.00067515432 | AO18: 0.00050981041 | AP18: 0.189 | AQ18: 0.00010683624 | AR18: -0.00043697338 | AS18: 1.0546591 | AT18: 1.015686 | AU18: 1.015686 | AV18: 1.1188578
A19: 45568 | B19: FALSE | C19: FALSE | D19: 2024ESZ | E19: C4 | F19: 5736.9 | H19: 0 | I19: 487.19697 | J19: 0.0483 | K19: 12472.387 | L19: 12443.923 | M19: 458.94638 | O19: 18.9 | P19: 12443.923 | Q19: 0.99627714 | T19: 0.065708187 | U19: 0.10338131 | V19: 0.10511322 | W19: 0.10511322 | X19: -0.0012741472 | Z19: 0.10835016 | AA19: 0.11406448 | AB19: 1.1301844 | AC19: -0.0040386633 | AD19: 485.77331 | AE19: 483.29253 | AG19: 485.77331 | AI19: 1.3069273e-05 | AK19: 461.03236 | AL19: 467.94784 | AM19: 454.11687 | AN19: 0.00050981041 | AO19: 0.00034446649 | AP19: 0.189 | AQ19: 1.5520819e-08 | AR19: -0.0012741627 | AS19: 1.0546591 | AT19: 1.0155142 | AU19: 1.0155142 | AV19: 1.1301844
A20: 45568 | B20: FALSE | C20: FALSE | D20: 2024ESZ | E20: C5 | F20: 5739.625 | H20: 0 | I20: 487.19697 | J20: 0.0483 | K20: 12472.387 | L20: 12449.692 | M20: 459.15915 | O20: 18.9 | P20: 12449.692 | Q20: 1.000475 | T20: 0.065708187 | U20: 0.10034525 | V20: 0.10357941 | W20: 0.10357941 | X20: -6.3084444e-06 | Z20: 0.10835016 | AA20: 0.11395635 | AB20: 1.1028867 | AC20: 0.00052122346 | AD20: 485.77331 | AE20: 483.54443 | AG20: 485.77331 | AI20: 2.1482516e-07 | AK20: 461.03236 | AL20: 467.94784 | AM20: 454.11687 | AN20: 0.00034446649 | AO20: 0.00017912257 | AP20: 0.189 | AQ20: 3.3343697e-14 | AR20: -6.3084444e-06 | AS20: 1.0546591 | AT20: 1.0080693 | AU20: 1.0080693 | AV20: 1.1028867
A21: 45568 | B21: FALSE | C21: FALSE | D21: 2024ESZ | E21: C6 | F21: 5741.9875 | H21: 0 | I21: 487.19697 | J21: 0.0483 | K21: 12472.387 | L21: 12454.396 | M21: 459.33264 | O21: 18.9 | P21: 12454.396 | Q21: 1.0004116 | T21: 0.065708187 | U21: 0.097365929 | V21: 0.10205089 | W21: 0.10205089 | X21: 0 | Z21: 0.10835016 | AA21: 0.1138963 | AB21: 1.1202445 | AC21: 0.00041497969 | AD21: 485.77331 | AE21: 483.7451 | AG21: 485.77331 | AI21: 1.4270965e-07 | AK21: 461.03236 | AL21: 467.94784 | AM21: 454.11687 | AN21: 0.00017912257 | AO21: 0 | AP21: 0.189 | AQ21: 0 | AR21: 0 | AS21: 1.0546591 | AT21: 1.0089936 | AU21: 1.0089936 | AV21: 1.1202445
A22: 45568 | B22: FALSE | C22: FALSE | D22: 2024ESZ | E22: C7 | F22: 5745.2 | G22: usual | H22: 0 | I22: 487.19697 | J22: 0.0483 | K22: 12472.387 | L22: 12462.073 | M22: 459.61578 | N22: 463.76413 | O22: 18.9 | P22: 12462.073 | Q22: 1.0005595 | R22: 463.76413 | S22: 0.067394869 | T22: 0.065708187 | U22: 0.094612403 | V22: 0.10060839 | W22: 0.10060839 | X22: 0 | Y22: 0.10698836 | Z22: 0.10835016 | AA22: 0.11379682 | AB22: 1.1376011 | AC22: 0.00068879297 | AD22: 485.77331 | AE22: 484.0783 | AF22: 484.0783 | AG22: 485.77331 | AH22: 45568 | AI22: 3.797258e-07 | AJ22: 459.61578 | AK22: 461.03236 | AL22: 467.94784 | AM22: 454.11687 | AN22: 0 | AO22: 0.0010058422 | AP22: 0.189 | AQ22: 0 | AR22: 0 | AS22: 1.0546591 | AT22: 1.0095062 | AU22: 1.0095062 | AV22: 1.1376011
A23: 45569 | B23: FALSE | C23: FALSE | D23: 2024ESZ | E23: C1 | F23: 5788.8 | H23: 0 | I23: 491.4762 | J23: 0.0483 | K23: 12586.911 | L23: 12559.735 | M23: 463.13162 | O23: 20.49 | P23: 12559.735 | Q23: 1.0075889 | T23: 0.067394869 | U23: 0.12066744 | V23: 0.11354072 | W23: 0.12066744 | X23: 0.11106155 | Z23: 0.10698836 | AA23: 0.1176846 | AB23: 1.154881 | AC23: 0.0086864968 | AD23: 484.0783 | AE23: 488.28324 | AG23: 484.0783 | AI23: 5.8070811e-05 | AK23: 459.61578 | AL23: 466.51001 | AM23: 452.72154 | AN23: 0.0010058422 | AO23: 0.00084049824 | AP23: 0.2049 | AQ23: 0.11112561 | AR23: -6.4060703e-05 | AS23: 1.0651195 | AT23: 1.0103541 | AU23: 1.0103541 | AV23: 1.154881
A24: 45569 | B24: FALSE | C24: FALSE | D24: 2024ESZ | E24: C2 | F24: 5762.9 | H24: 0 | I24: 491.4762 | J24: 0.0483 | K24: 12586.911 | L24: 12506.146 | M24: 461.15556 | O24: 20.49 | P24: 12506.146 | Q24: 0.99552584 | T24: 0.067394869 | U24: 0.12498825 | V24: 0.11607017 | W24: 0.12498825 | X24: 0.014909698 | Z24: 0.10698836 | AA24: 0.1189202 | AB24: 1.0325805 | AC24: -0.0049397955 | AD24: 484.0783 | AE24: 485.87122 | AG24: 484.0783 | AI24: 1.8282967e-05 | AK24: 459.61578 | AL24: 466.51001 | AM24: 452.72154 | AN24: 0.00084049824 | AO24: 0.00067515432 | AP24: 0.2049 | AQ24: 0.015170317 | AR24: -0.00026061863 | AS24: 1.0651195 | AT24: 0.97609749 | AU24: 0.97609749 | AV24: 1.0325805
A25: 45569 | B25: FALSE | C25: FALSE | D25: 2024ESZ | E25: C3 | F25: 5763.475 | H25: 0 | I25: 491.4762 | J25: 0.0483 | K25: 12586.911 | L25: 12506.025 | M25: 461.1511 | O25: 20.49 | P25: 12506.025 | Q25: 1.0000998 | T25: 0.067394869 | U25: 0.12118064 | V25: 0.11431588 | W25: 0.12118064 | X25: 0.0062645337 | Z25: 0.10698836 | AA25: 0.11758696 | AB25: 0.89649052 | AC25: -2.3599464e-05 | AD25: 484.0783 | AE25: 485.85975 | AG25: 484.0783 | AI25: 9.361123e-11 | AK25: 459.61578 | AL25: 466.51001 | AM25: 452.72154 | AN25: 0.00067515432 | AO25: 0.00050981041 | AP25: 0.2049 | AQ25: 0.0062975776 | AR25: -3.3043947e-05 | AS25: 1.0651195 | AT25: 0.96470754 | AU25: 0.96470754 | AV25: 0.89649052
A26: 45569 | B26: FALSE | C26: FALSE | D26: 2024ESZ | E26: C4 | F26: 5781.8125 | H26: 0 | I26: 491.4762 | J26: 0.0483 | K26: 12586.911 | L26: 12545.061 | M26: 462.59053 | O26: 20.49 | P26: 12545.061 | Q26: 1.0031817 | T26: 0.067394869 | U26: 0.12178527 | V26: 0.11484803 | W26: 0.12178527 | X26: 0.013321059 | Z26: 0.10698836 | AA26: 0.11792685 | AB26: 0.9364286 | AC26: 0.0027942897 | AD26: 484.0783 | AE26: 487.21739 | AG26: 484.0783 | AI26: 9.7126602e-06 | AK26: 459.61578 | AL26: 466.51001 | AM26: 452.72154 | AN26: 0.00050981041 | AO26: 0.00034446649 | AP26: 0.2049 | AQ26: 0.013321066 | AR26: -7.0332666e-09 | AS26: 1.0651195 | AT26: 0.97698683 | AU26: 0.97698683 | AV26: 0.9364286
A27: 45569 | B27: FALSE | C27: FALSE | D27: 2024ESZ | E27: C5 | F27: 5780.025 | H27: 0 | I27: 491.4762 | J27: 0.0483 | K27: 12586.911 | L27: 12540.774 | M27: 462.43245 | O27: 20.49 | P27: 12540.774 | Q27: 0.99969084 | T27: 0.067394869 | U27: 0.11812754 | V27: 0.11313952 | W27: 0.11812754 | X27: 0.00068728189 | Z27: 0.10698836 | AA27: 0.11758394 | AB27: 0.92882048 | AC27: -0.00032076479 | AD27: 484.0783 | AE27: 487.06111 | AG27: 484.0783 | AI27: 1.1681802e-07 | AK27: 459.61578 | AL27: 466.51001 | AM27: 452.72154 | AN27: 0.00034446649 | AO27: 0.00017912257 | AP27: 0.2049 | AQ27: 0.00068728189 | AR27: -4.9960036e-15 | AS27: 1.0651195 | AT27: 0.97388422 | AU27: 0.97388422 | AV27: 0.92882048
A28: 45569 | B28: FALSE | C28: FALSE | D28: 2024ESZ | E28: C6 | F28: 5781.25 | H28: 0 | I28: 491.4762 | J28: 0.0483 | K28: 12586.911 | L28: 12542.392 | M28: 462.49211 | O28: 20.49 | P28: 12542.392 | Q28: 1.0002119 | T28: 0.067394869 | U28: 0.11453659 | V28: 0.11143346 | W28: 0.11453659 | X28: 0 | Z28: 0.10698836 | AA28: 0.11755628 | AB28: 0.95114693 | AC28: 0.00011760298 | AD28: 484.0783 | AE28: 487.11839 | AG28: 484.0783 | AI28: 1.6643794e-08 | AK28: 459.61578 | AL28: 466.51001 | AM28: 452.72154 | AN28: 0.00017912257 | AO28: 0 | AP28: 0.2049 | AQ28: 0 | AR28: 0 | AS28: 1.0651195 | AT28: 0.97701436 | AU28: 0.97701436 | AV28: 0.95114693
A29: 45569 | B29: FALSE | C29: FALSE | D29: 2024ESZ | E29: C7 | F29: 5798.675 | G29: usual | H29: 0 | I29: 491.4762 | J29: 0.0483 | K29: 12586.911 | L29: 12580.145 | M29: 463.88423 | N29: 468.08074 | O29: 20.49 | P29: 12580.145 | Q29: 1.0030141 | R29: 468.08074 | S29: 0.064529511 | T29: 0.067394869 | U29: 0.11527175 | V29: 0.11190587 | W29: 0.11527175 | X29: 0 | Y29: 0.10683632 | Z29: 0.10698836 | AA29: 0.11736584 | AB29: 0.98121999 | AC29: 0.0028599753 | AD29: 484.0783 | AE29: 488.51153 | AF29: 488.51153 | AG29: 484.0783 | AH29: 45569 | AI29: 9.0330953e-06 | AJ29: 463.88423 | AK29: 459.61578 | AL29: 466.51001 | AM29: 452.72154 | AN29: 0 | AO29: 0.0010058422 | AP29: 0.2049 | AQ29: 0 | AR29: 0 | AS29: 1.0651195 | AT29: 0.97726604 | AU29: 0.97726604 | AV29: 0.98121999
A30: 45572 | B30: FALSE | C30: FALSE | D30: 2024ESZ | E30: C1 | F30: 5778.125 | H30: 0 | I30: 486.79446 | J30: 0.0483 | K30: 12466.41 | L30: 12540.122 | M30: 462.15895 | O30: 19.21 | P30: 12540.122 | Q30: 0.99645609 | T30: 0.064529511 | U30: 0.11815161 | V30: 0.11349879 | W30: 0.11815161 | X30: -0.019884976 | Z30: 0.10683632 | AA30: 0.11804141 | AB30: 0.97668728 | AC30: -0.0036914613 | AD30: 488.51153 | AE30: 486.70821 | AG30: 488.51153 | AI30: 1.3883979e-05 | AK30: 463.88423 | AL30: 470.84249 | AM30: 456.92596 | AN30: 0.0010058422 | AO30: 0.00084049824 | AP30: 0.1921 | AQ30: 0.00041944182 | AR30: -0.020304418 | AS30: 1.0662728 | AT30: 0.97899522 | AU30: 0.97899522 | AV30: 0.97668728
A31: 45572 | B31: FALSE | C31: FALSE | D31: 2024ESZ | E31: C2 | F31: 5781.35 | H31: 0 | I31: 486.79446 | J31: 0.0483 | K31: 12466.41 | L31: 12546.493 | M31: 462.39375 | O31: 19.21 | P31: 12546.493 | Q31: 1.0005581 | T31: 0.064529511 | U31: 0.11467135 | V31: 0.1118444 | W31: 0.11467135 | X31: -0.0083801148 | Z31: 0.10683632 | AA31: 0.11041427 | AB31: 0.9279469 | AC31: 0.00049133124 | AD31: 488.51153 | AE31: 486.94735 | AG31: 488.51153 | AI31: 2.57983e-07 | AK31: 463.88423 | AL31: 470.84249 | AM31: 456.92596 | AN31: 0.00084049824 | AO31: 0.00067515432 | AP31: 0.1921 | AQ31: 0.00014445166 | AR31: -0.0085245664 | AS31: 1.0662728 | AT31: 0.97283422 | AU31: 0.97283422 | AV31: 0.9279469
A32: 45572 | B32: FALSE | C32: FALSE | D32: 2024ESZ | E32: C3 | F32: 5782.05 | H32: 0 | I32: 486.79446 | J32: 0.0483 | K32: 12466.41 | L32: 12548.843 | M32: 462.48036 | O32: 19.21 | P32: 12548.843 | Q32: 1.0001211 | T32: 0.064529511 | U32: 0.11119469 | V32: 0.11016238 | W32: 0.11119469 | X32: -0.0026346669 | Z32: 0.10683632 | AA32: 0.10969848 | AB32: 1.0309084 | AC32: 0.00016351141 | AD32: 488.51153 | AE32: 487.02697 | AG32: 488.51153 | AI32: 3.507597e-08 | AK32: 463.88423 | AL32: 470.84249 | AM32: 456.92596 | AN32: 0.00067515432 | AO32: 0.00050981041 | AP32: 0.1921 | AQ32: 1.8200714e-05 | AR32: -0.0026528676 | AS32: 1.0662728 | AT32: 1.0383457 | AU32: 1.0383457 | AV32: 1.0309084
A33: 45572 | B33: FALSE | C33: FALSE | D33: 2024ESZ | E33: C4 | F33: 5773.975 | H33: 0 | I33: 486.79446 | J33: 0.0483 | K33: 12466.41 | L33: 12530.608 | M33: 461.80832 | O33: 19.21 | P33: 12530.608 | Q33: 0.99860344 | T33: 0.064529511 | U33: 0.10884033 | V33: 0.10901186 | W33: 0.10901186 | X33: -0.0014278256 | Z33: 0.10683632 | AA33: 0.1098021 | AB33: 1.0797967 | AC33: -0.0015029245 | AD33: 488.51153 | AE33: 486.295 | AG33: 488.51153 | AI33: 2.114636e-06 | AK33: 463.88423 | AL33: 470.84249 | AM33: 456.92596 | AN33: 0.00050981041 | AO33: 0.00034446649 | AP33: 0.1921 | AQ33: 2.7844218e-08 | AR33: -0.0014278534 | AS33: 1.0662728 | AT33: 1.0440666 | AU33: 1.0440666 | AV33: 1.0797967
A34: 45572 | B34: FALSE | C34: FALSE | D34: 2024ESZ | E34: C5 | F34: 5770.025 | H34: 0 | I34: 486.79446 | J34: 0.0483 | K34: 12466.41 | L34: 12522.933 | M34: 461.52546 | O34: 19.21 | P34: 12522.933 | Q34: 0.9993159 | T34: 0.064529511 | U34: 0.1057127 | V34: 0.1074567 | W34: 0.1074567 | X34: -4.869865e-05 | Z34: 0.10683632 | AA34: 0.10984171 | AB34: 1.1005492 | AC34: -0.00066345095 | AD34: 488.51153 | AE34: 485.97237 | AG34: 488.51153 | AI34: 3.7538642e-07 | AK34: 463.88423 | AL34: 470.84249 | AM34: 456.92596 | AN34: 0.00034446649 | AO34: 0.00017912257 | AP34: 0.1921 | AQ34: 3.8479426e-15 | AR34: -4.869865e-05 | AS34: 1.0662728 | AT34: 1.0432427 | AU34: 1.0432427 | AV34: 1.1005492
A35: 45572 | B35: FALSE | C35: FALSE | D35: 2024ESZ | E35: C6 | F35: 5741.225 | H35: 0 | I35: 486.79446 | J35: 0.0483 | K35: 12466.41 | L35: 12460.454 | M35: 459.22284 | O35: 19.21 | P35: 12460.454 | Q35: 0.99500869 | T35: 0.064529511 | U35: 0.11468398 | V35: 0.11191251 | W35: 0.11468398 | X35: 0 | Z35: 0.10683632 | AA35: 0.11158622 | AB35: 1.1161392 | AC35: -0.0054923824 | AD35: 488.51153 | AE35: 483.30322 | AG35: 488.51153 | AI35: 2.5016544e-05 | AK35: 463.88423 | AL35: 470.84249 | AM35: 456.92596 | AN35: 0.00017912257 | AO35: 0 | AP35: 0.1921 | AQ35: 0 | AR35: 0 | AS35: 1.0662728 | AT35: 1.0429273 | AU35: 1.0429273 | AV35: 1.1161392
A36: 45572 | B36: FALSE | C36: FALSE | D36: 2024ESZ | E36: C7 | F36: 5747.5 | G36: usual | H36: 0 | I36: 486.79446 | J36: 0.0483 | K36: 12466.41 | L36: 12470.818 | M36: 459.6048 | N36: 463.94979 | O36: 19.21 | P36: 12470.818 | Q36: 1.001093 | R36: 463.94979 | S36: 0.063450703 | T36: 0.064529511 | U36: 0.11151875 | V36: 0.11038686 | W36: 0.11151875 | X36: 0 | Y36: 0.10789492 | Z36: 0.10683632 | AA36: 0.11161775 | AB36: 1.0316639 | AC36: 0.00091990284 | AD36: 488.51153 | AE36: 483.74782 | AF36: 483.74782 | AG36: 488.51153 | AH36: 45572 | AI36: 6.9123541e-07 | AJ36: 459.6048 | AK36: 463.88423 | AL36: 470.84249 | AM36: 456.92596 | AN36: 0 | AO36: 0.0010058422 | AP36: 0.1921 | AQ36: 0 | AR36: 0 | AS36: 1.0662728 | AT36: 1.0288289 | AU36: 1.0288289 | AV36: 1.0316639
A37: 45573 | B37: FALSE | C37: FALSE | D37: 2024ESZ | E37: C1 | F37: 5768.15 | H37: 0 | I37: 491.51857 | J37: 0.0483 | K37: 12587.255 | L37: 12516.921 | M37: 461.22289 | O37: 22.64 | P37: 12516.921 | Q37: 1.0035929 | T37: 0.063450703 | U37: 0.11400659 | V37: 0.11168406 | W37: 0.11400659 | X37: 0.039602536 | Z37: 0.10789492 | AA37: 0.11170415 | AB37: 1.0606788 | AC37: 0.0036153046 | AD37: 483.74782 | AE37: 485.49671 | AG37: 483.74782 | AI37: 1.2351259e-05 | AK37: 459.6048 | AL37: 466.49887 | AM37: 452.71072 | AN37: 0.0010058422 | AO37: 0.00084049824 | AP37: 0.2264 | AQ37: 0.041848671 | AR37: -0.0022461354 | AS37: 1.0581821 | AT37: 1.0285702 | AU37: 1.0285702 | AV37: 1.0606788
A38: 45573 | B38: FALSE | C38: FALSE | D38: 2024ESZ | E38: C2 | F38: 5789.7 | H38: 0 | I38: 491.51857 | J38: 0.0483 | K38: 12587.255 | L38: 12564.755 | M38: 462.98547 | O38: 22.64 | P38: 12564.755 | Q38: 1.003736 | T38: 0.063450703 | U38: 0.11729227 | V38: 0.1134418 | W38: 0.11729227 | X38: 0.099825192 | Z38: 0.10789492 | AA38: 0.11245238 | AB38: 1.0782899 | AC38: 0.0040516727 | AD38: 483.74782 | AE38: 487.46378 | AG38: 483.74782 | AI38: 1.4548604e-05 | AK38: 459.6048 | AL38: 466.49887 | AM38: 452.71072 | AN38: 0.00084049824 | AO38: 0.00067515432 | AP38: 0.2264 | AQ38: 0.099892488 | AR38: -6.7295524e-05 | AS38: 1.0581821 | AT38: 1.0278608 | AU38: 1.0278608 | AV38: 1.0782899
A39: 45573 | B39: FALSE | C39: FALSE | D39: 2024ESZ | E39: C3 | F39: 5790.225 | H39: 0 | I39: 491.51857 | J39: 0.0483 | K39: 12587.255 | L39: 12565.009 | M39: 462.99483 | O39: 22.64 | P39: 12565.009 | Q39: 1.0000907 | T39: 0.063450703 | U39: 0.11371927 | V39: 0.11172731 | W39: 0.11371927 | X39: 0.070453631 | Z39: 0.10789492 | AA39: 0.11222277 | AB39: 1.1018768 | AC39: 1.9439234e-05 | AD39: 483.74782 | AE39: 487.47326 | AG39: 483.74782 | AI39: 4.0864915e-10 | AK39: 459.6048 | AL39: 466.49887 | AM39: 452.71072 | AN39: 0.00067515432 | AO39: 0.00050981041 | AP39: 0.2264 | AQ39: 0.070459125 | AR39: -5.4944219e-06 | AS39: 1.0581821 | AT39: 1.021673 | AU39: 1.021673 | AV39: 1.1018768
A40: 45573 | B40: FALSE | C40: FALSE | D40: 2024ESZ | E40: C4 | F40: 5788.25 | H40: 0 | I40: 491.51857 | J40: 0.0483 | K40: 12587.255 | L40: 12560.795 | M40: 462.83956 | O40: 22.64 | P40: 12560.795 | Q40: 0.99965891 | T40: 0.063450703 | U40: 0.11030891 | V40: 0.11006569 | W40: 0.11030891 | X40: 0.030598798 | Z40: 0.10789492 | AA40: 0.11192658 | AB40: 1.1075656 | AC40: -0.0003701117 | AD40: 483.74782 | AE40: 487.29284 | AG40: 483.74782 | AI40: 1.1251466e-07 | AK40: 459.6048 | AL40: 466.49887 | AM40: 452.71072 | AN40: 0.00050981041 | AO40: 0.00034446649 | AP40: 0.2264 | AQ40: 0.030598867 | AR40: -6.8947906e-08 | AS40: 1.0581821 | AT40: 1.0235802 | AU40: 1.0235802 | AV40: 1.1075656
...

Sheet Prev Calc
A1: Window | B1: FUTURE TWAP Current | C1: FUTURE TWAP Next | D1: INDEX TWAP | E1: Date | F1: CODE | G1: IS_PARTIAL | H1: IS_ROLL | I1: EXPERY_DAY | J1: 3 DAYS BEFORE EXPERY | K1: IS_EXPIRY | L1: ES1_PAR_C4_FIX | M1: ES_ROLL_FIX | N1: SwitchESData | O1: ES_TWAP | P1: ES_TWAP_RATIO | Q1: ROLL_FUT_IDX | R1: SP_TWAP_PAR_C4_FIX | S1: SP_TWAP_ROLL_FIX | T1: DATE_FOR_FT | U1: SPXT_Last | V1: ROLL_FUT_IDX_Last | W1: FINAN_FEE | X1: FINAN_FEE_FOR_CALC | Y1: SP_TWAP_RATIO | Z1: FINAL_TWAP_RATIO | AA1: EQ_INTRA_LVL | AB1: EQ_LOGRET | AC1: EQ_LOGRETsqrt | AD1: EQVOL_ST | AE1: EQVOL_LT | AF1: EQVOL | AG1: EQ_LAST_LVL | AH1: EQ_LVL_FOR_STRIKE | AI1: VIX_FOR_DELTA | AJ1: CALL_STRIKE | AK1: PUT_STRIKE | AL1: ITTE | AM1: ITTE T+1 AUX | AN1: DELTA_CALL | AP1: DELTA | AQ1: DAILY_120D_VOL | AR1: DAILY_120D_VOL_FOR_VAF | AS1: DAILY_120D_VAF | AT1: INTRADAY_21D_VAF | AU1: TargetPart | AV1: FCVHL | AW1: FCVHL_RETURN | AX1: PARTICIPATION | AY1: INTRADAY_21D_VOL | AZ1: ICL_DATE | BA1: ICL | BB1: OFFICIAL LVL | BC1: ABS DIFF | BD1: DATE
A2: C1 | B2: 4602.675 | C2: 0 | D2: 9844.3 | E2: 45139 | F2: 2023-08-01C1 | G2: FALSE | H2: FALSE | I2: FALSE | J2: FALSE | K2: FALSE | L2: 4602.675 | M2: 4602.675 | N2: FALSE | O2: 4602.675 | P2: 0.99907748 | Q2: 393.6944 | R2: 9844.3 | S2: 9844.3 | X2: 0.0533 | Y2: 0.99916907 | Z2: 0.99916907 | AA2: 390.03774 | AB2: -0.000831274 | AC2: 6.91e-07 | AD2: 0.11062399 | AE2: 0.10778051 | AF2: 0.11062399 | AH2: 390.3621 | AI2: 13.63 | AJ2: 396.21753 | AK2: 384.50667 | AL2: 0.001005842 | AM2: 0.000840498 | AN2: 3.5e-05 | AO2: -0.00014938 | AP2: -0.000114369 | AR2: 0.11926823 | AS2: 0.96145323 | AT2: 0.9757315 | AU2: 0.97194628 | AV2: 425.29817 | AW2: -0.000798742 | AX2: 0.97194628 | AY2: 0.11760163 | BD2: 45139
A3: C2 | B3: 4600.125 | C3: 0 | D3: 9839.071 | E3: 45139 | F3: 2023-08-01C2 | G3: FALSE | H3: FALSE | I3: FALSE | J3: FALSE | K3: FALSE | L3: 4600.125 | M3: 4600.125 | N3: FALSE | O3: 4600.125 | P3: 0.99944597 | Q3: 393.47629 | R3: 9839.071 | S3: 9839.071 | X3: 0.0533 | Y3: 0.99946883 | Z3: 0.99946883 | AA3: 389.83056 | AB3: -0.000531311 | AC3: 2.82e-07 | AD3: 0.10739313 | AE3: 0.10622184 | AF3: 0.10739313 | AH3: 390.3621 | AI3: 13.63 | AJ3: 396.21753 | AK3: 384.50667 | AL3: 0.000840498 | AM3: 0.000675154 | AN3: 2.25e-06 | AO3: -5.13e-05 | AP3: -4.9e-05 | AR3: 0.11926823 | AS3: 0.96145323 | AT3: 0.97685333 | AU3: 0.99948593 | AV3: 425.07743 | AW3: -0.000519023 | AX3: 0.99948593 | AY3: 0.11756638 | BD3: 45139
A4: C3 | B4: 4596.4 | C4: 0 | D4: 9831.735 | E4: 45139 | F4: 2023-08-01C3 | G4: FALSE | H4: FALSE | I4: FALSE | J4: FALSE | K4: FALSE | L4: 4596.4 | M4: 4596.4 | N4: FALSE | O4: 4596.4 | P4: 0.99919024 | Q4: 393.15767 | R4: 9831.735 | S4: 9831.735 | X4: 0.0533 | Y4: 0.9992544 | Z4: 0.9992544 | AA4: 389.5399 | AB4: -0.000745877 | AC4: 5.56e-07 | AD4: 0.10440388 | AE4: 0.10475699 | AF4: 0.10475699 | AH4: 390.3621 | AI4: 13.63 | AJ4: 396.21753 | AK4: 384.50667 | AL4: 0.000675154 | AM4: 0.00050981 | AN4: 1.68e-08 | AO4: -1.18e-05 | AP4: -1.18e-05 | AR4: 0.11926823 | AS4: 0.96145323 | AT4: 0.97717411 | AU4: 1.0295549 | AV4: 424.75938 | AW4: -0.000748222 | AX4: 1.0295549 | AY4: 0.11750051 | BD4: 45139
A5: C4 | B5: 4597.25 | C5: 0 | D5: 9833.261 | E5: 45139 | F5: 2023-08-01C4 | G5: FALSE | H5: FALSE | I5: FALSE | J5: FALSE | K5: FALSE | L5: 4597.25 | M5: 4597.25 | N5: FALSE | O5: 4597.25 | P5: 1.0001849 | Q5: 393.23037 | R5: 9833.261 | S5: 9833.261 | X5: 0.0533 | Y5: 1.0001552 | Z5: 1.0001552 | AA5: 389.60036 | AB5: 0.0001552 | AC5: 2.41e-08 | AD5: 0.10123591 | AE5: 0.10317985 | AF5: 0.10317985 | AH5: 390.3621 | AI5: 13.63 | AJ5: 396.21753 | AK5: 384.50667 | AL5: 0.00050981 | AM5: 0.000344466 | AN5: 1.4e-11 | AO5: -9.77e-08 | AP5: -9.77e-08 | AR5: 0.11926823 | AS5: 0.96145323 | AT5: 0.977773 | AU5: 1.0554629 | AV5: 424.82616 | AW5: 0.000157208 | AX5: 1.0554629 | AY5: 0.11023706 | BD5: 45139
A6: C5 | B6: 4598.9125 | C6: 0 | D6: 9837.032 | E6: 45139 | F6: 2023-08-01C5 | G6: FALSE | H6: FALSE | I6: FALSE | J6: FALSE | K6: FALSE | L6: 4598.9125 | M6: 4598.9125 | N6: FALSE | O6: 4598.9125 | P6: 1.0003616 | Q6: 393.37257 | R6: 9837.032 | S6: 9837.032 | X6: 0.0533 | Y6: 1.0003835 | Z6: 1.0003835 | AA6: 389.74977 | AB6: 0.000383421 | AC6: 1.47e-07 | AD6: 0.098231087 | AE6: 0.10165864 | AF6: 0.10165864 | AH6: 390.3621 | AI6: 13.63 | AJ6: 396.21753 | AK6: 384.50667 | AL6: 0.000344466 | AM6: 0.000179123 | AN6: 9.28e-20 | AO6: -5.62e-14 | AP6: -5.62e-14 | AR6: 0.11926823 | AS6: 0.96145323 | AT6: 1.0397684 | AU6: 1.0715961 | AV6: 424.99743 | AW6: 0.000403151 | AX6: 1.0715961 | AY6: 0.11023496 | BD6: 45139
A7: C6 | B7: 4603.85 | C7: 0 | D7: 9847.978 | E7: 45139 | F7: 2023-08-01C6 | G7: FALSE | H7: FALSE | I7: FALSE | J7: FALSE | K7: FALSE | L7: 4603.85 | M7: 4603.85 | N7: FALSE | O7: 4603.85 | P7: 1.0010736 | Q7: 393.79491 | R7: 9847.978 | S7: 9847.978 | X7: 0.0533 | Y7: 1.0011127 | Z7: 1.0011127 | AA7: 390.18346 | AB7: 0.001112115 | AC7: 1.24e-06 | AD7: 0.095923348 | AE7: 0.10044847 | AF7: 0.10044847 | AH7: 390.3621 | AI7: 13.63 | AJ7: 396.21753 | AK7: 384.50667 | AL7: 0.000179123 | AM7: 0 | AN7: 0 | AO7: 0 | AP7: 0 | AR7: 0.11926823 | AS7: 0.96145323 | AT7: 1.0397853 | AU7: 1.0876314 | AV7: 425.50351 | AW7: 0.001190798 | AX7: 1.0876314 | AY7: 0.11023177 | BD7: 45139
A8: C7 | B8: 4602.9 | C8: 0 | D8: 9845.137 | E8: 45139 | F8: 2023-08-01C7 | G8: FALSE | H8: FALSE | I8: FALSE | J8: FALSE | K8: FALSE | L8: 4602.9 | M8: 4602.9 | N8: FALSE | O8: 4602.9 | P8: 0.99979365 | Q8: 393.71365 | R8: 9845.137 | S8: 9845.137 | T8: 45139 | U8: 9845.137 | V8: 393.71365 | W8: 0.0533 | X8: 0.0533 | Y8: 0.99971151 | Z8: 0.99971151 | AA8: 390.0709 | AB8: -0.000288527 | AC8: 8.32e-08 | AD8: 0.093048494 | AE8: 0.098952534 | AF8: 0.098952534 | AG8: 390.0709 | AH8: 390.3621 | AI8: 13.63 | AJ8: 396.21753 | AK8: 384.50667 | AL8: 0 | AN8: 0 | AO8: 0 | AP8: 0 | AQ8: 0.11862292 | AR8: 0.11926823 | AS8: 0.96145323 | AT8: 1.0398108 | AU8: 1.1007347 | AV8: 425.36945 | AW8: -0.000315076 | AX8: 1.1007347 | AY8: 0.10998393 | AZ8: 45139 | BA8: 425.36945 | BB8: 425.36944 | BC8: 7.09e-06 | BD8: 45139
A9: C1 | B9: 4564.425 | C9: 0 | D9: 9765.052 | E9: 45140 | F9: 2023-08-02C1 | G9: FALSE | H9: FALSE | I9: FALSE | J9: FALSE | K9: FALSE | L9: 4564.425 | M9: 4564.425 | N9: FALSE | O9: 4564.425 | P9: 0.99164114 | Q9: 390.42265 | R9: 9765.052 | S9: 9765.052 | X9: 0.0533 | Y9: 0.99171747 | Z9: 0.99171747 | AA9: 386.84013 | AB9: -0.008317019 | AC9: 6.92e-05 | AD9: 0.12433741 | AE9: 0.11471042 | AF9: 0.12433741 | AH9: 390.0709 | AI9: 13.93 | AJ9: 395.92196 | AK9: 384.21984 | AL9: 0.001005842 | AM9: 0.000840498 | AN9: 4.62e-09 | AO9: -0.045996441 | AP9: -0.045996437 | AR9: 0.11862292 | AS9: 0.96747103 | AT9: 1.0417934 | AU9: 1.1243691 | AV9: 421.4845 | AW9: -0.009133119 | AX9: 1.1243691 | AY9: 0.11457859 | BD9: 45140
A10: C2 | B10: 4545.825 | C10: 0 | D10: 9725.409 | E10: 45140 | F10: 2023-08-02C2 | G10: FALSE | H10: FALSE | I10: FALSE | J10: FALSE | K10: FALSE | L10: 4545.825 | M10: 4545.825 | N10: FALSE | O10: 4545.825 | P10: 0.99592501 | Q10: 388.83168 | R10: 9725.409 | S10: 9725.409 | X10: 0.0533 | Y10: 0.99594032 | Z10: 0.99594032 | AA10: 385.26968 | AB10: -0.004067944 | AC10: 1.65e-05 | AD10: 0.12760745 | AE10: 0.11678808 | AF10: 0.12760745 | AH10: 390.0709 | AI10: 13.93 | AJ10: 395.92196 | AK10: 384.21984 | AL10: 0.000840498 | AM10: 0.000675154 | AN10: 2.47e-14 | AO10: -0.22491925 | AP10: -0.22491925 | AR10: 0.11862292 | AS10: 0.96747103 | AT10: 1.0036511 | AU10: 0.85007571 | AV10: 419.55006 | AW10: -0.00458958 | AX10: 0.87436906 | AY10: 0.11572065 | BD10: 45140
